<?xml version="1.0" encoding="utf-8"?>
<!-- This URDF was automatically created by SolidWorks to URDF Exporter! Originally created by Stephen Brawner (brawner@gmail.com) 
     Commit Version: 1.6.0-1-g15f4949  Build Version: 1.6.7594.29634
     For more information, please see http://wiki.ros.org/sw_urdf_exporter -->
<robot
  name="I3_dual_arm">
  <link
    name="TORSO">
    <inertial>
      <origin
        xyz="-0.00297588264259219 0.000931485180964531 0.0525826662858528"
        rpy="0 0 0" />
      <mass
        value="21.557192" />
      <inertia
        ixx="0.423255"
        ixy="0.002555"
        ixz="-0.012414"
        iyy="0.308298"
        iyz="0.000759"
        izz="0.292344" />
    </inertial>
    <visual>
      <origin
        xyz="0 0 0"
        rpy="0 0 0" />
      <geometry>
        <mesh
          filename="package://I3_250610/meshes/TORSO.STL" />
      </geometry>
      <material
        name="">
        <color
          rgba="0.898039215686275 0.917647058823529 0.929411764705882 1" />
      </material>
    </visual>
    <collision>
      <origin
        xyz="0 0 0"
        rpy="0 0 0" />
      <geometry>
        <mesh
          filename="package://I3_250610/meshes/TORSO.STL" />
      </geometry>
    </collision>
  </link>
  <link
    name="SCAPULA_L">
    <inertial>
      <origin
        xyz="0.00209369087149947 0.0699013277268586 -0.000418280171970764"
        rpy="0 0 0" />
      <mass
        value="1.257536" />
      <inertia
        ixx="0.001680"
        ixy="-0.000010"
        ixz="-0.000009"
        iyy="0.001439"
        iyz="0.000063"
        izz="0.001777" />
    </inertial>
    <visual>
      <origin
        xyz="0 0 0"
        rpy="0 0 0" />
      <geometry>
        <mesh
          filename="package://I3_250610/meshes/SCAPULA_L.STL" />
      </geometry>
      <material
        name="">
        <color
          rgba="0.698039215686274 0.698039215686274 0.698039215686274 1" />
      </material>
    </visual>
    <collision>
      <origin
        xyz="0 0 0"
        rpy="0 0 0" />
      <geometry>
        <mesh
          filename="package://I3_250610/meshes/SCAPULA_L.STL" />
      </geometry>
    </collision>
  </link>
  <joint
    name="Shoulder_Y_L"
    type="revolute">
    <origin
      xyz="0 0.16876 0.1472"
      rpy="0.17453 0 0" />
    <parent
      link="TORSO" />
    <child
      link="SCAPULA_L" />
    <axis
      xyz="0 1 0" />
    <limit
      lower="-3.316"
      upper="1.221"
      effort="57"
      velocity="3.56" />
  </joint>
  <link
    name="SHOULDER_L">
    <inertial>
      <origin
        xyz="0.00698545986627741 0.0122331494825563 -0.0433203761743293"
        rpy="0 0 0" />
      <mass
        value="0.630636" />
      <inertia
        ixx="0.001877"
        ixy="-0.000051"
        ixz="0.000122"
        iyy="0.002026"
        iyz="-0.000199"
        izz="0.001772" />
    </inertial>
    <visual>
      <origin
        xyz="0 0 0"
        rpy="0 0 0" />
      <geometry>
        <mesh
          filename="package://I3_250610/meshes/SHOULDER_L.STL" />
      </geometry>
      <material
        name="">
        <color
          rgba="0.898039215686275 0.917647058823529 0.929411764705882 1" />
      </material>
    </visual>
    <collision>
      <origin
        xyz="0 0 0"
        rpy="0 0 0" />
      <geometry>
        <mesh
          filename="package://I3_250610/meshes/SHOULDER_L.STL" />
      </geometry>
    </collision>
  </link>
  <joint
    name="Shoulder_X_L"
    type="revolute">
    <origin
      xyz="0 0.07803 0"
      rpy="-0.17453 0 0" />
    <parent
      link="SCAPULA_L" />
    <child
      link="SHOULDER_L" />
    <axis
      xyz="1 0 0" />
    <limit
      lower="-0.008"
      upper="3.141"
      effort="57"
      velocity="3.56" />
  </joint>
  <link
    name="UPPERARM_L">
    <inertial>
      <origin
        xyz="-0.000539212478610218 2.81531782553301E-06 -0.081819202792502"
        rpy="0 0 0" />
      <mass
        value="1.951375" />
      <inertia
        ixx="0.011891"
        ixy="0.000002"
        ixz="0.000008"
        iyy="0.011895"
        iyz="0.000098"
        izz="0.001809" />
    </inertial>
    <visual>
      <origin
        xyz="0 0 0"
        rpy="0 0 0" />
      <geometry>
        <mesh
          filename="package://I3_250610/meshes/UPPERARM_L.STL" />
      </geometry>
      <material
        name="">
        <color
          rgba="0.698039215686274 0.698039215686274 0.698039215686274 1" />
      </material>
    </visual>
    <collision>
      <origin
        xyz="0 0 0"
        rpy="0 0 0" />
      <geometry>
        <mesh
          filename="package://I3_250610/meshes/UPPERARM_L.STL" />
      </geometry>
    </collision>
  </link>
  <joint
    name="Shoulder_Z_L"
    type="revolute">
    <origin
      xyz="0 0.01 -0.09918"
      rpy="0 0 0" />
    <parent
      link="SHOULDER_L" />
    <child
      link="UPPERARM_L" />
    <axis
      xyz="0 0 1" />
    <limit
      lower="-2.967"
      upper="2.967"
      effort="57"
      velocity="3.56" />
  </joint>
  <link
    name="FOREARM_L">
    <inertial>
      <origin
        xyz="-0.0039090321801537 0.00331501433337911 -0.111365427960743"
        rpy="0 0 0" />
      <mass
        value="0.441102" />
      <inertia
        ixx="0.003322"
        ixy="0.000001"
        ixz="-0.000105"
        iyy="0.003193"
        iyz="0.000011"
        izz="0.000689" />
    </inertial>
    <visual>
      <origin
        xyz="0 0 0"
        rpy="0 0 0" />
      <geometry>
        <mesh
          filename="package://I3_250610/meshes/FOREARM_L.STL" />
      </geometry>
      <material
        name="">
        <color
          rgba="0.498039215686275 0.498039215686275 0.498039215686275 1" />
      </material>
    </visual>
    <collision>
      <origin
        xyz="0 0 0"
        rpy="0 0 0" />
      <geometry>
        <mesh
          filename="package://I3_250610/meshes/FOREARM_L.STL" />
      </geometry>
    </collision>
  </link>
  <joint
    name="Elbow_L"
    type="revolute">
    <origin
      xyz="0 0 -0.1827"
      rpy="0 0 0" />
    <parent
      link="UPPERARM_L" />
    <child
      link="FOREARM_L" />
    <axis
      xyz="0 1 0" />
    <limit
      lower="-2.094"
      upper="0.087"
      effort="31"
      velocity="3.665" />
  </joint>
  <link
    name="HAND_L">
    <inertial>
      <origin
        xyz="-0.00905981066196138 0.00134895304620664 0.0687953456532113"
        rpy="0 0 0" />
      <mass
        value="0.629922" />
      <inertia
        ixx="0.000964"
        ixy="-0.000057"
        ixz="0.000095"
        iyy="0.001420"
        iyz="0.000031"
        izz="0.000569" />
    </inertial>
    <visual>
      <origin
        xyz="0 0 0"
        rpy="0 0 0" />
      <geometry>
        <mesh
          filename="package://I3_250610/meshes/HAND_L.STL" />
      </geometry>
      <material
        name="">
        <color
          rgba="0.898039215686275 0.917647058823529 0.929411764705882 1" />
      </material>
    </visual>
    <collision>
      <origin
        xyz="0 0 0"
        rpy="0 0 0" />
      <geometry>
        <mesh
          filename="package://I3_250610/meshes/HAND_L.STL" />
      </geometry>
    </collision>
  </link>
  <joint
    name="Hand_L"
    type="fixed">
    <origin
      xyz="0 0 -0.269099999999994"
      rpy="3.14159265358979 0 3.14159265358979" />
    <parent
      link="FOREARM_L" />
    <child
      link="HAND_L" />
    <axis
      xyz="0 0 0" />
  </joint>
  <link
    name="SCAPULA_R">
    <inertial>
      <origin
        xyz="0.00209339905817796 -0.0698946350951941 -0.000698515222583129"
        rpy="0 0 0" />
      <mass
        value="1.257580" />
      <inertia
        ixx="0.001679"
        ixy="0.000012"
        ixz="0.000004"
        iyy="0.001434"
        iyz="-0.000051"
        izz="0.001781" />
    </inertial>
    <visual>
      <origin
        xyz="0 0 0"
        rpy="0 0 0" />
      <geometry>
        <mesh
          filename="package://I3_250610/meshes/SCAPULA_R.STL" />
      </geometry>
      <material
        name="">
        <color
          rgba="0.898039215686275 0.917647058823529 0.929411764705882 1" />
      </material>
    </visual>
    <collision>
      <origin
        xyz="0 0 0"
        rpy="0 0 0" />
      <geometry>
        <mesh
          filename="package://I3_250610/meshes/SCAPULA_R.STL" />
      </geometry>
    </collision>
  </link>
  <joint
    name="Shoulder_Y_R"
    type="revolute">
    <origin
      xyz="0 -0.16876 0.1472"
      rpy="-0.17453 0 0" />
    <parent
      link="TORSO" />
    <child
      link="SCAPULA_R" />
    <axis
      xyz="0 1 0" />
    <limit
      lower="-3.316"
      upper="1.221"
      effort="57"
      velocity="3.56" />
  </joint>
  <link
    name="SHOULDER_R">
    <inertial>
      <origin
        xyz="0.00442941605218694 -0.0129878455097245 -0.0448871989039477"
        rpy="0 0 0" />
      <mass
        value="0.598974" />
      <inertia
        ixx="0.001803"
        ixy="0.000028"
        ixz="0.000075"
        iyy="0.001897"
        iyz="0.000183"
        izz="0.001672" />
    </inertial>
    <visual>
      <origin
        xyz="0 0 0"
        rpy="0 0 0" />
      <geometry>
        <mesh
          filename="package://I3_250610/meshes/SHOULDER_R.STL" />
      </geometry>
      <material
        name="">
        <color
          rgba="0.792156862745098 0.819607843137255 0.933333333333333 1" />
      </material>
    </visual>
    <collision>
      <origin
        xyz="0 0 0"
        rpy="0 0 0" />
      <geometry>
        <mesh
          filename="package://I3_250610/meshes/SHOULDER_R.STL" />
      </geometry>
    </collision>
  </link>
  <joint
    name="Shoulder_X_R"
    type="revolute">
    <origin
      xyz="0 -0.07803 0"
      rpy="0.17453 0 0" />
    <parent
      link="SCAPULA_R" />
    <child
      link="SHOULDER_R" />
    <axis
      xyz="1 0 0" />
    <limit
      lower="-3.141"
      upper="0.008"
      effort="57"
      velocity="3.56" />
  </joint>
  <link
    name="UPPERARM_R">
    <inertial>
      <origin
        xyz="-5.82833655987658E-05 -0.000411824176190789 -0.0817957607544104"
        rpy="0 0 0" />
      <mass
        value="1.950597" />
      <inertia
        ixx="0.011880"
        ixy="-0.000004"
        ixz="0.000009"
        iyy="0.011899"
        iyz="-0.000111"
        izz="0.001810" />
    </inertial>
    <visual>
      <origin
        xyz="0 0 0"
        rpy="0 0 0" />
      <geometry>
        <mesh
          filename="package://I3_250610/meshes/UPPERARM_R.STL" />
      </geometry>
      <material
        name="">
        <color
          rgba="0.698039215686274 0.698039215686274 0.698039215686274 1" />
      </material>
    </visual>
    <collision>
      <origin
        xyz="0 0 0"
        rpy="0 0 0" />
      <geometry>
        <mesh
          filename="package://I3_250610/meshes/UPPERARM_R.STL" />
      </geometry>
    </collision>
  </link>
  <joint
    name="Shoulder_Z_R"
    type="revolute">
    <origin
      xyz="0 -0.01 -0.09918"
      rpy="0 0 0" />
    <parent
      link="SHOULDER_R" />
    <child
      link="UPPERARM_R" />
    <axis
      xyz="0 0 1" />
    <limit
      lower="-2.967"
      upper="2.967"
      effort="57"
      velocity="3.56" />
  </joint>
  <link
    name="FOREARM_R">
    <inertial>
      <origin
        xyz="-0.00390617849608332 -0.00331534676342837 -0.111363108997059"
        rpy="0 0 0" />
      <mass
        value="0.440899" />
      <inertia
        ixx="0.003319"
        ixy="-0.000001"
        ixz="-0.000104"
        iyy="0.003190"
        iyz="-0.000011"
        izz="0.000689" />
    </inertial>
    <visual>
      <origin
        xyz="0 0 0"
        rpy="0 0 0" />
      <geometry>
        <mesh
          filename="package://I3_250610/meshes/FOREARM_R.STL" />
      </geometry>
      <material
        name="">
        <color
          rgba="1 1 1 1" />
      </material>
    </visual>
    <collision>
      <origin
        xyz="0 0 0"
        rpy="0 0 0" />
      <geometry>
        <mesh
          filename="package://I3_250610/meshes/FOREARM_R.STL" />
      </geometry>
    </collision>
  </link>
  <joint
    name="Elbow_R"
    type="revolute">
    <origin
      xyz="0 0 -0.1827"
      rpy="0 0 0" />
    <parent
      link="UPPERARM_R" />
    <child
      link="FOREARM_R" />
    <axis
      xyz="0 1 0" />
    <limit
      lower="-2.094"
      upper="0.087"
      effort="35"
      velocity="3.665" />
  </joint>
  <link
    name="HAND_R">
    <inertial>
      <origin
        xyz="-0.00928790592218209 -0.00185089547687234 0.068787614136257"
        rpy="0 0 0" />
      <mass
        value="0.629974" />
      <inertia
        ixx="0.000957"
        ixy="0.000045"
        ixz="0.000096"
        iyy="0.001435"
        iyz="-0.000038"
        izz="0.000576" />
    </inertial>
    <visual>
      <origin
        xyz="0 0 0"
        rpy="0 0 0" />
      <geometry>
        <mesh
          filename="package://I3_250610/meshes/HAND_R.STL" />
      </geometry>
      <material
        name="">
        <color
          rgba="0.898039215686275 0.917647058823529 0.929411764705882 1" />
      </material>
    </visual>
    <collision>
      <origin
        xyz="0 0 0"
        rpy="0 0 0" />
      <geometry>
        <mesh
          filename="package://I3_250610/meshes/HAND_R.STL" />
      </geometry>
    </collision>
  </link>
  <joint
    name="Hand_R"
    type="fixed">
    <origin
      xyz="0 0 -0.2691"
      rpy="3.14159265358979 0 3.14159265358979" />
    <parent
      link="FOREARM_R" />
    <child
      link="HAND_R" />
    <axis
      xyz="0 0 0" />
  </joint>
  <link
    name="NECK">
    <inertial>
      <origin
        xyz="4.88595474112952E-06 1.30309971253517E-05 -0.00350506438671294"
        rpy="0 0 0" />
      <mass
        value="0.267748" />
      <inertia
        ixx="0.000113"
        ixy="0.000000"
        ixz="0.000000"
        iyy="0.000090"
        iyz="0.000010"
        izz="0.000094" />
    </inertial>
    <visual>
      <origin
        xyz="0 0 0"
        rpy="0 0 0" />
      <geometry>
        <mesh
          filename="package://I3_250610/meshes/NECK.STL" />
      </geometry>
      <material
        name="">
        <color
          rgba="0.898039215686275 0.917647058823529 0.929411764705882 1" />
      </material>
    </visual>
    <collision>
      <origin
        xyz="0 0 0"
        rpy="0 0 0" />
      <geometry>
        <mesh
          filename="package://I3_250610/meshes/NECK.STL" />
      </geometry>
    </collision>
  </link>
  <joint
    name="Neck_Z"
    type="revolute">
    <origin
      xyz="0.02 0 0.331"
      rpy="0 0 0" />
    <parent
      link="TORSO" />
    <child
      link="NECK" />
    <axis
      xyz="0 0 1" />
    <limit
      lower="-0.785"
      upper="0.785"
      effort="7"
      velocity="3.665" />
  </joint>
  <link
    name="HEAD">
    <inertial>
      <origin
        xyz="0.0134099868746256 -0.000691557518617492 0.0829764021613855"
        rpy="0 0 0" />
      <mass
        value="0.827300" />
      <inertia
        ixx="0.003849"
        ixy="0.000006"
        ixz="-0.000329"
        iyy="0.003877"
        iyz="0.000055"
        izz="0.003988" />
    </inertial>
    <visual>
      <origin
        xyz="0 0 0"
        rpy="0 0 0" />
      <geometry>
        <mesh
          filename="package://I3_250610/meshes/HEAD.STL" />
      </geometry>
      <material
        name="">
        <color
          rgba="1 1 1 1" />
      </material>
    </visual>
    <collision>
      <origin
        xyz="0 0 0"
        rpy="0 0 0" />
      <geometry>
        <mesh
          filename="package://I3_250610/meshes/HEAD.STL" />
      </geometry>
    </collision>
  </link>
  <joint
    name="Neck_Y"
    type="revolute">
    <origin
      xyz="0 0 0"
      rpy="0 0 0" />
    <parent
      link="NECK" />
    <child
      link="HEAD" />
    <axis
      xyz="0 1 0" />
    <limit
      lower="-0.436"
      upper="0.436"
      effort="7"
      velocity="3.665" />
  </joint>
</robot>